Workbook

Sheet PO-Backlog
A1: PO-Backlog
A2: # | B2: Projekttitel | C2: Größe | D2: Value-Bucket | E2: Quartal | F2: MoSCoW | G2: Team | H2: Std. | I2: Bemerkungen
A3: 1 | B3: Doku - LogIn für Kunden | F3: Could | G3: WEB
A4: 2 | B4: Auswertung zur Nutzung / Verhalten MILO | F4: Could | G4: WEB | H4: =IF(C4="XXL (>160h)",168,IF(C4="XL (>40h)",48,IF(C4="L (20-40h)",30,IF(C4="M (10-20h)",15,IF(C4="S (<10h)",5,""))))) | J4: =IF($E4="Q12026",COUNTIF($E$3:$E4,"Q12026"),"") | K4: =IF($E4="Q22026",COUNTIF($E$3:$E4,"Q22026"),"") | L4: =IF($E4="Q32026",COUNTIF($E$3:$E4,"Q32026"),"") | M4: =IF($E4="Q42026",COUNTIF($E$3:$E4,"Q42026"),"") | N4: =IF($E4="Backlog",COUNTIF($E$3:$E4,"Backlog"),"")
A5: 3 | B5: Integration von MILO auf der Homepage | F5: Could | G5: WEB | H5: =IF(C5="XXL (>160h)",168,IF(C5="XL (>40h)",48,IF(C5="L (20-40h)",30,IF(C5="M (10-20h)",15,IF(C5="S (<10h)",5,""))))) | J5: =IF($E5="Q12026",COUNTIF($E$3:$E5,"Q12026"),"") | K5: =IF($E5="Q22026",COUNTIF($E$3:$E5,"Q22026"),"") | L5: =IF($E5="Q32026",COUNTIF($E$3:$E5,"Q32026"),"") | M5: =IF($E5="Q42026",COUNTIF($E$3:$E5,"Q42026"),"") | N5: =IF($E5="Backlog",COUNTIF($E$3:$E5,"Backlog"),"")
A6: 4 | B6: Refactoring / Optimierung MILO | F6: Could | G6: WEB | H6: =IF(C6="XXL (>160h)",168,IF(C6="XL (>40h)",48,IF(C6="L (20-40h)",30,IF(C6="M (10-20h)",15,IF(C6="S (<10h)",5,""))))) | J6: =IF($E6="Q12026",COUNTIF($E$3:$E6,"Q12026"),"") | K6: =IF($E6="Q22026",COUNTIF($E$3:$E6,"Q22026"),"") | L6: =IF($E6="Q32026",COUNTIF($E$3:$E6,"Q32026"),"") | M6: =IF($E6="Q42026",COUNTIF($E$3:$E6,"Q42026"),"") | N6: =IF($E6="Backlog",COUNTIF($E$3:$E6,"Backlog"),"")
A7: 5 | B7: Technical debt / Hypertron -> GitHub -> CI/CD | F7: Should | G7: WEB | H7: =IF(C7="XXL (>160h)",168,IF(C7="XL (>40h)",48,IF(C7="L (20-40h)",30,IF(C7="M (10-20h)",15,IF(C7="S (<10h)",5,""))))) | I7: auch als Basis für AI Maturity -> Volaris | J7: =IF($E7="Q12026",COUNTIF($E$3:$E7,"Q12026"),"") | K7: =IF($E7="Q22026",COUNTIF($E$3:$E7,"Q22026"),"") | L7: =IF($E7="Q32026",COUNTIF($E$3:$E7,"Q32026"),"") | M7: =IF($E7="Q42026",COUNTIF($E$3:$E7,"Q42026"),"") | N7: =IF($E7="Backlog",COUNTIF($E$3:$E7,"Backlog"),"")
A8: 6 | B8: Angular | F8: Must | G8: WEB | H8: =IF(C8="XXL (>160h)",168,IF(C8="XL (>40h)",48,IF(C8="L (20-40h)",30,IF(C8="M (10-20h)",15,IF(C8="S (<10h)",5,""))))) | J8: =IF($E8="Q12026",COUNTIF($E$3:$E8,"Q12026"),"") | K8: =IF($E8="Q22026",COUNTIF($E$3:$E8,"Q22026"),"") | L8: =IF($E8="Q32026",COUNTIF($E$3:$E8,"Q32026"),"") | M8: =IF($E8="Q42026",COUNTIF($E$3:$E8,"Q42026"),"") | N8: =IF($E8="Backlog",COUNTIF($E$3:$E8,"Backlog"),"")
A9: 7 | B9: Andorid Anforderungen | E9: Q42026 | F9: Must | G9: WEB | H9: =IF(C9="XXL (>160h)",168,IF(C9="XL (>40h)",48,IF(C9="L (20-40h)",30,IF(C9="M (10-20h)",15,IF(C9="S (<10h)",5,""))))) | I9: -> relevant bis August 2026 | J9: =IF($E9="Q12026",COUNTIF($E$3:$E9,"Q12026"),"") | K9: =IF($E9="Q22026",COUNTIF($E$3:$E9,"Q22026"),"") | L9: =IF($E9="Q32026",COUNTIF($E$3:$E9,"Q32026"),"") | M9: =IF($E9="Q42026",COUNTIF($E$3:$E9,"Q42026"),"") -> 1 | N9: =IF($E9="Backlog",COUNTIF($E$3:$E9,"Backlog"),"")
A10: 8 | B10: Grundlasten berücksichtigen [ SIG / Incidents / Framework / etc. ] | F10: Must | G10: W->D | H10: =IF(C10="XXL (>160h)",168,IF(C10="XL (>40h)",48,IF(C10="L (20-40h)",30,IF(C10="M (10-20h)",15,IF(C10="S (<10h)",5,""))))) | J10: =IF($E10="Q12026",COUNTIF($E$3:$E10,"Q12026"),"") | K10: =IF($E10="Q22026",COUNTIF($E$3:$E10,"Q22026"),"") | L10: =IF($E10="Q32026",COUNTIF($E$3:$E10,"Q32026"),"") | M10: =IF($E10="Q42026",COUNTIF($E$3:$E10,"Q42026"),"") | N10: =IF($E10="Backlog",COUNTIF($E$3:$E10,"Backlog"),"")
A11: 9 | B11: Webshop - abweichende Lieferadresse + extra Namensfeld | F11: Should | G11: WEB | H11: =IF(C11="XXL (>160h)",168,IF(C11="XL (>40h)",48,IF(C11="L (20-40h)",30,IF(C11="M (10-20h)",15,IF(C11="S (<10h)",5,""))))) | J11: =IF($E11="Q12026",COUNTIF($E$3:$E11,"Q12026"),"") | K11: =IF($E11="Q22026",COUNTIF($E$3:$E11,"Q22026"),"") | L11: =IF($E11="Q32026",COUNTIF($E$3:$E11,"Q32026"),"") | M11: =IF($E11="Q42026",COUNTIF($E$3:$E11,"Q42026"),"") | N11: =IF($E11="Backlog",COUNTIF($E$3:$E11,"Backlog"),"")
A12: 10 | B12: Webshop - neues Feld Firmenname bei Gastfunktion | F12: Should | G12: WEB | H12: =IF(C12="XXL (>160h)",168,IF(C12="XL (>40h)",48,IF(C12="L (20-40h)",30,IF(C12="M (10-20h)",15,IF(C12="S (<10h)",5,""))))) | J12: =IF($E12="Q12026",COUNTIF($E$3:$E12,"Q12026"),"") | K12: =IF($E12="Q22026",COUNTIF($E$3:$E12,"Q22026"),"") | L12: =IF($E12="Q32026",COUNTIF($E$3:$E12,"Q32026"),"") | M12: =IF($E12="Q42026",COUNTIF($E$3:$E12,"Q42026"),"") | N12: =IF($E12="Backlog",COUNTIF($E$3:$E12,"Backlog"),"")
A13: 11 | B13: Paypal - integration muss zeitnah erneuert werden | F13: Must | G13: WEB | H13: =IF(C13="XXL (>160h)",168,IF(C13="XL (>40h)",48,IF(C13="L (20-40h)",30,IF(C13="M (10-20h)",15,IF(C13="S (<10h)",5,""))))) | J13: =IF($E13="Q12026",COUNTIF($E$3:$E13,"Q12026"),"") | K13: =IF($E13="Q22026",COUNTIF($E$3:$E13,"Q22026"),"") | L13: =IF($E13="Q32026",COUNTIF($E$3:$E13,"Q32026"),"") | M13: =IF($E13="Q42026",COUNTIF($E$3:$E13,"Q42026"),"") | N13: =IF($E13="Backlog",COUNTIF($E$3:$E13,"Backlog"),"")
A14: 12 | B14: DOKUMENTATION - Next Steps / V2? / | F14: Must | G14: W->D | H14: =IF(C14="XXL (>160h)",168,IF(C14="XL (>40h)",48,IF(C14="L (20-40h)",30,IF(C14="M (10-20h)",15,IF(C14="S (<10h)",5,""))))) | J14: =IF($E14="Q12026",COUNTIF($E$3:$E14,"Q12026"),"") | K14: =IF($E14="Q22026",COUNTIF($E$3:$E14,"Q22026"),"") | L14: =IF($E14="Q32026",COUNTIF($E$3:$E14,"Q32026"),"") | M14: =IF($E14="Q42026",COUNTIF($E$3:$E14,"Q42026"),"") | N14: =IF($E14="Backlog",COUNTIF($E$3:$E14,"Backlog"),"")
A15: 13 | B15: Reserv with Google / oder andere Anbindungen verbessern | H15: =IF(C15="XXL (>160h)",168,IF(C15="XL (>40h)",48,IF(C15="L (20-40h)",30,IF(C15="M (10-20h)",15,IF(C15="S (<10h)",5,""))))) | J15: =IF($E15="Q12026",COUNTIF($E$3:$E15,"Q12026"),"") | K15: =IF($E15="Q22026",COUNTIF($E$3:$E15,"Q22026"),"") | L15: =IF($E15="Q32026",COUNTIF($E$3:$E15,"Q32026"),"") | M15: =IF($E15="Q42026",COUNTIF($E$3:$E15,"Q42026"),"") | N15: =IF($E15="Backlog",COUNTIF($E$3:$E15,"Backlog"),"")
A16: 14 | B16: Jouney Gaps (2) | H16: =IF(C16="XXL (>160h)",168,IF(C16="XL (>40h)",48,IF(C16="L (20-40h)",30,IF(C16="M (10-20h)",15,IF(C16="S (<10h)",5,""))))) | J16: =IF($E16="Q12026",COUNTIF($E$3:$E16,"Q12026"),"") | K16: =IF($E16="Q22026",COUNTIF($E$3:$E16,"Q22026"),"") | L16: =IF($E16="Q32026",COUNTIF($E$3:$E16,"Q32026"),"") | M16: =IF($E16="Q42026",COUNTIF($E$3:$E16,"Q42026"),"") | N16: =IF($E16="Backlog",COUNTIF($E$3:$E16,"Backlog"),"")
A17: 15 | B17: Prosegur Cash Automat API | H17: =IF(C17="XXL (>160h)",168,IF(C17="XL (>40h)",48,IF(C17="L (20-40h)",30,IF(C17="M (10-20h)",15,IF(C17="S (<10h)",5,""))))) | J17: =IF($E17="Q12026",COUNTIF($E$3:$E17,"Q12026"),"") | K17: =IF($E17="Q22026",COUNTIF($E$3:$E17,"Q22026"),"") | L17: =IF($E17="Q32026",COUNTIF($E$3:$E17,"Q32026"),"") | M17: =IF($E17="Q42026",COUNTIF($E$3:$E17,"Q42026"),"") | N17: =IF($E17="Backlog",COUNTIF($E$3:$E17,"Backlog"),"")
A18: 16 | B18: Bei der Walletanbindung von Gutscheinen, sollten wir auch gleich die Tickets berücksichtigen. | H18: =IF(C18="XXL (>160h)",168,IF(C18="XL (>40h)",48,IF(C18="L (20-40h)",30,IF(C18="M (10-20h)",15,IF(C18="S (<10h)",5,""))))) | J18: =IF($E18="Q12026",COUNTIF($E$3:$E18,"Q12026"),"") | K18: =IF($E18="Q22026",COUNTIF($E$3:$E18,"Q22026"),"") | L18: =IF($E18="Q32026",COUNTIF($E$3:$E18,"Q32026"),"") | M18: =IF($E18="Q42026",COUNTIF($E$3:$E18,"Q42026"),"") | N18: =IF($E18="Backlog",COUNTIF($E$3:$E18,"Backlog"),"")
A19: 17 | B19: UHD | Jahresrechnung | H19: =IF(C19="XXL (>160h)",168,IF(C19="XL (>40h)",48,IF(C19="L (20-40h)",30,IF(C19="M (10-20h)",15,IF(C19="S (<10h)",5,""))))) | J19: =IF($E19="Q12026",COUNTIF($E$3:$E19,"Q12026"),"") | K19: =IF($E19="Q22026",COUNTIF($E$3:$E19,"Q22026"),"") | L19: =IF($E19="Q32026",COUNTIF($E$3:$E19,"Q32026"),"") | M19: =IF($E19="Q42026",COUNTIF($E$3:$E19,"Q42026"),"") | N19: =IF($E19="Backlog",COUNTIF($E$3:$E19,"Backlog"),"")
A20: 18 | B20: Neue DATEV-Schnittstelle | H20: =IF(C20="XXL (>160h)",168,IF(C20="XL (>40h)",48,IF(C20="L (20-40h)",30,IF(C20="M (10-20h)",15,IF(C20="S (<10h)",5,""))))) | J20: =IF($E20="Q12026",COUNTIF($E$3:$E20,"Q12026"),"") | K20: =IF($E20="Q22026",COUNTIF($E$3:$E20,"Q22026"),"") | L20: =IF($E20="Q32026",COUNTIF($E$3:$E20,"Q32026"),"") | M20: =IF($E20="Q42026",COUNTIF($E$3:$E20,"Q42026"),"") | N20: =IF($E20="Backlog",COUNTIF($E$3:$E20,"Backlog"),"")
A21: 19 | B21: Subventionierungsmodul im Webshop / Retail / Inhouse Ordering | Kundenstamm 1 vs. Kundenstamm 2.0 -> Mail von Dennis | H21: =IF(C21="XXL (>160h)",168,IF(C21="XL (>40h)",48,IF(C21="L (20-40h)",30,IF(C21="M (10-20h)",15,IF(C21="S (<10h)",5,""))))) | J21: =IF($E21="Q12026",COUNTIF($E$3:$E21,"Q12026"),"") | K21: =IF($E21="Q22026",COUNTIF($E$3:$E21,"Q22026"),"") | L21: =IF($E21="Q32026",COUNTIF($E$3:$E21,"Q32026"),"") | M21: =IF($E21="Q42026",COUNTIF($E$3:$E21,"Q42026"),"") | N21: =IF($E21="Backlog",COUNTIF($E$3:$E21,"Backlog"),"")
A22: 20 | B22: Eventfunktion auch für Gruppen aktiviert im IHO | H22: =IF(C22="XXL (>160h)",168,IF(C22="XL (>40h)",48,IF(C22="L (20-40h)",30,IF(C22="M (10-20h)",15,IF(C22="S (<10h)",5,""))))) | J22: =IF($E22="Q12026",COUNTIF($E$3:$E22,"Q12026"),"") | K22: =IF($E22="Q22026",COUNTIF($E$3:$E22,"Q22026"),"") | L22: =IF($E22="Q32026",COUNTIF($E$3:$E22,"Q32026"),"") | M22: =IF($E22="Q42026",COUNTIF($E$3:$E22,"Q42026"),"") | N22: =IF($E22="Backlog",COUNTIF($E$3:$E22,"Backlog"),"")
A23: 21 | B23: Adyen Tokenization und Network Tokenization -> Mail von Lars / 27.01.2026 | H23: =IF(C23="XXL (>160h)",168,IF(C23="XL (>40h)",48,IF(C23="L (20-40h)",30,IF(C23="M (10-20h)",15,IF(C23="S (<10h)",5,""))))) | I23: Wunsch noch in 2026 (Q3?) | Ausarbeitung fehlt | J23: =IF($E23="Q12026",COUNTIF($E$3:$E23,"Q12026"),"") | K23: =IF($E23="Q22026",COUNTIF($E$3:$E23,"Q22026"),"") | L23: =IF($E23="Q32026",COUNTIF($E$3:$E23,"Q32026"),"") | M23: =IF($E23="Q42026",COUNTIF($E$3:$E23,"Q42026"),"") | N23: =IF($E23="Backlog",COUNTIF($E$3:$E23,"Backlog"),"")
A24: 22 | B24: NoCoo auch in anderen Sprachen (primär englisch / gerne merhsprachig) | H24: =IF(C24="XXL (>160h)",168,IF(C24="XL (>40h)",48,IF(C24="L (20-40h)",30,IF(C24="M (10-20h)",15,IF(C24="S (<10h)",5,""))))) | J24: =IF($E24="Q12026",COUNTIF($E$3:$E24,"Q12026"),"") | K24: =IF($E24="Q22026",COUNTIF($E$3:$E24,"Q22026"),"") | L24: =IF($E24="Q32026",COUNTIF($E$3:$E24,"Q32026"),"") | M24: =IF($E24="Q42026",COUNTIF($E$3:$E24,"Q42026"),"") | N24: =IF($E24="Backlog",COUNTIF($E$3:$E24,"Backlog"),"")
A25: 23 | B25: Gekündigte Kunden dürfen nicht mehr auf das Portal zugreifen - Mail Sebastian 19.02.2026 | H25: =IF(C25="XXL (>160h)",168,IF(C25="XL (>40h)",48,IF(C25="L (20-40h)",30,IF(C25="M (10-20h)",15,IF(C25="S (<10h)",5,""))))) | J25: =IF($E25="Q12026",COUNTIF($E$3:$E25,"Q12026"),"") | K25: =IF($E25="Q22026",COUNTIF($E$3:$E25,"Q22026"),"") | L25: =IF($E25="Q32026",COUNTIF($E$3:$E25,"Q32026"),"") | M25: =IF($E25="Q42026",COUNTIF($E$3:$E25,"Q42026"),"") | N25: =IF($E25="Backlog",COUNTIF($E$3:$E25,"Backlog"),"")
A26: 24 | B26: Den MyHypersoft-Login vor die Doku schalten. - Mail Sebastian 19.02.2026 | H26: =IF(C26="XXL (>160h)",168,IF(C26="XL (>40h)",48,IF(C26="L (20-40h)",30,IF(C26="M (10-20h)",15,IF(C26="S (<10h)",5,""))))) | J26: =IF($E26="Q12026",COUNTIF($E$3:$E26,"Q12026"),"") | K26: =IF($E26="Q22026",COUNTIF($E$3:$E26,"Q22026"),"") | L26: =IF($E26="Q32026",COUNTIF($E$3:$E26,"Q32026"),"") | M26: =IF($E26="Q42026",COUNTIF($E$3:$E26,"Q42026"),"") | N26: =IF($E26="Backlog",COUNTIF($E$3:$E26,"Backlog"),"")
A27: 25 | B27: UHD - Pflichtfeld „Benutzer“ (Hinweis, wenn keine Mail -> Eingabe) | H27: =IF(C27="XXL (>160h)",168,IF(C27="XL (>40h)",48,IF(C27="L (20-40h)",30,IF(C27="M (10-20h)",15,IF(C27="S (<10h)",5,""))))) | J27: =IF($E27="Q12026",COUNTIF($E$3:$E27,"Q12026"),"") | K27: =IF($E27="Q22026",COUNTIF($E$3:$E27,"Q22026"),"") | L27: =IF($E27="Q32026",COUNTIF($E$3:$E27,"Q32026"),"") | M27: =IF($E27="Q42026",COUNTIF($E$3:$E27,"Q42026"),"") | N27: =IF($E27="Backlog",COUNTIF($E$3:$E27,"Backlog"),"")
A28: 26 | B28: UHD - Ticket-Owner hinterlegen | H28: =IF(C28="XXL (>160h)",168,IF(C28="XL (>40h)",48,IF(C28="L (20-40h)",30,IF(C28="M (10-20h)",15,IF(C28="S (<10h)",5,""))))) | J28: =IF($E28="Q12026",COUNTIF($E$3:$E28,"Q12026"),"") | K28: =IF($E28="Q22026",COUNTIF($E$3:$E28,"Q22026"),"") | L28: =IF($E28="Q32026",COUNTIF($E$3:$E28,"Q32026"),"") | M28: =IF($E28="Q42026",COUNTIF($E$3:$E28,"Q42026"),"") | N28: =IF($E28="Backlog",COUNTIF($E$3:$E28,"Backlog"),"")
A29: 27 | B29: UHD - Autoresponder bei eingehenden Mails. (SLA) | H29: =IF(C29="XXL (>160h)",168,IF(C29="XL (>40h)",48,IF(C29="L (20-40h)",30,IF(C29="M (10-20h)",15,IF(C29="S (<10h)",5,""))))) | J29: =IF($E29="Q12026",COUNTIF($E$3:$E29,"Q12026"),"") | K29: =IF($E29="Q22026",COUNTIF($E$3:$E29,"Q22026"),"") | L29: =IF($E29="Q32026",COUNTIF($E$3:$E29,"Q32026"),"") | M29: =IF($E29="Q42026",COUNTIF($E$3:$E29,"Q42026"),"") | N29: =IF($E29="Backlog",COUNTIF($E$3:$E29,"Backlog"),"")
A30: 28 | B30: UHD - Incident-Antworten mit Company-Mail in CC (SLA) – An welche Mail? | H30: =IF(C30="XXL (>160h)",168,IF(C30="XL (>40h)",48,IF(C30="L (20-40h)",30,IF(C30="M (10-20h)",15,IF(C30="S (<10h)",5,""))))) | J30: =IF($E30="Q12026",COUNTIF($E$3:$E30,"Q12026"),"") | K30: =IF($E30="Q22026",COUNTIF($E$3:$E30,"Q22026"),"") | L30: =IF($E30="Q32026",COUNTIF($E$3:$E30,"Q32026"),"") | M30: =IF($E30="Q42026",COUNTIF($E$3:$E30,"Q42026"),"") | N30: =IF($E30="Backlog",COUNTIF($E$3:$E30,"Backlog"),"")
A31: 29 | B31: UHD - Parsing | H31: =IF(C31="XXL (>160h)",168,IF(C31="XL (>40h)",48,IF(C31="L (20-40h)",30,IF(C31="M (10-20h)",15,IF(C31="S (<10h)",5,""))))) | J31: =IF($E31="Q12026",COUNTIF($E$3:$E31,"Q12026"),"") | K31: =IF($E31="Q22026",COUNTIF($E$3:$E31,"Q22026"),"") | L31: =IF($E31="Q32026",COUNTIF($E$3:$E31,"Q32026"),"") | M31: =IF($E31="Q42026",COUNTIF($E$3:$E31,"Q42026"),"") | N31: =IF($E31="Backlog",COUNTIF($E$3:$E31,"Backlog"),"")
A32: 30 | B32: Optimierung Gruppenwarenkorb / Tutorial-Modus / inhouse Ordering / Menüreihenfolge | H32: =IF(C32="XXL (>160h)",168,IF(C32="XL (>40h)",48,IF(C32="L (20-40h)",30,IF(C32="M (10-20h)",15,IF(C32="S (<10h)",5,""))))) | J32: =IF($E32="Q12026",COUNTIF($E$3:$E32,"Q12026"),"") | K32: =IF($E32="Q22026",COUNTIF($E$3:$E32,"Q22026"),"") | L32: =IF($E32="Q32026",COUNTIF($E$3:$E32,"Q32026"),"") | M32: =IF($E32="Q42026",COUNTIF($E$3:$E32,"Q42026"),"") | N32: =IF($E32="Backlog",COUNTIF($E$3:$E32,"Backlog"),"")
A33: 31 | B33: QR-Code auf der Zwischenrechnung zum Zahlprozess (Chamäleon Berlin) | H33: =IF(C33="XXL (>160h)",168,IF(C33="XL (>40h)",48,IF(C33="L (20-40h)",30,IF(C33="M (10-20h)",15,IF(C33="S (<10h)",5,""))))) | I33: NoCOO PAY | J33: =IF($E33="Q12026",COUNTIF($E$3:$E33,"Q12026"),"") | K33: =IF($E33="Q22026",COUNTIF($E$3:$E33,"Q22026"),"") | L33: =IF($E33="Q32026",COUNTIF($E$3:$E33,"Q32026"),"") | M33: =IF($E33="Q42026",COUNTIF($E$3:$E33,"Q42026"),"") | N33: =IF($E33="Backlog",COUNTIF($E$3:$E33,"Backlog"),"")
A34: 32 | B34: Widerruf im Onlineshop (Pflicht ab 19.06.2026) | E34: Q42026 | H34: =IF(C34="XXL (>160h)",168,IF(C34="XL (>40h)",48,IF(C34="L (20-40h)",30,IF(C34="M (10-20h)",15,IF(C34="S (<10h)",5,""))))) | I34: Erst einmal nicht bzw. nur oberflächlcih prüfen und validiern. | J34: =IF($E34="Q12026",COUNTIF($E$3:$E34,"Q12026"),"") | K34: =IF($E34="Q22026",COUNTIF($E$3:$E34,"Q22026"),"") | L34: =IF($E34="Q32026",COUNTIF($E$3:$E34,"Q32026"),"") | M34: =IF($E34="Q42026",COUNTIF($E$3:$E34,"Q42026"),"") -> 2 | N34: =IF($E34="Backlog",COUNTIF($E$3:$E34,"Backlog"),"")
A35: 33 | B35: KI-Prompt-Interface für den Desktop-UHD. Eventuell mittels "MCP" | E35: Q32026 | H35: =IF(C35="XXL (>160h)",168,IF(C35="XL (>40h)",48,IF(C35="L (20-40h)",30,IF(C35="M (10-20h)",15,IF(C35="S (<10h)",5,""))))) | J35: =IF($E35="Q12026",COUNTIF($E$3:$E35,"Q12026"),"") | K35: =IF($E35="Q22026",COUNTIF($E$3:$E35,"Q22026"),"") | L35: =IF($E35="Q32026",COUNTIF($E$3:$E35,"Q32026"),"") -> 1 | M35: =IF($E35="Q42026",COUNTIF($E$3:$E35,"Q42026"),"") | N35: =IF($E35="Backlog",COUNTIF($E$3:$E35,"Backlog"),"")
A36: 34 | B36: Touchpoint-Lizensierung | E36: Q32026 | H36: =IF(C36="XXL (>160h)",168,IF(C36="XL (>40h)",48,IF(C36="L (20-40h)",30,IF(C36="M (10-20h)",15,IF(C36="S (<10h)",5,""))))) | J36: =IF($E36="Q12026",COUNTIF($E$3:$E36,"Q12026"),"") | K36: =IF($E36="Q22026",COUNTIF($E$3:$E36,"Q22026"),"") | L36: =IF($E36="Q32026",COUNTIF($E$3:$E36,"Q32026"),"") -> 2 | M36: =IF($E36="Q42026",COUNTIF($E$3:$E36,"Q42026"),"") | N36: =IF($E36="Backlog",COUNTIF($E$3:$E36,"Backlog"),"")
A37: 35 | H37: =IF(C37="XXL (>160h)",168,IF(C37="XL (>40h)",48,IF(C37="L (20-40h)",30,IF(C37="M (10-20h)",15,IF(C37="S (<10h)",5,""))))) | J37: =IF($E37="Q12026",COUNTIF($E$3:$E37,"Q12026"),"") | K37: =IF($E37="Q22026",COUNTIF($E$3:$E37,"Q22026"),"") | L37: =IF($E37="Q32026",COUNTIF($E$3:$E37,"Q32026"),"") | M37: =IF($E37="Q42026",COUNTIF($E$3:$E37,"Q42026"),"") | N37: =IF($E37="Backlog",COUNTIF($E$3:$E37,"Backlog"),"")
A38: 36 | H38: =IF(C38="XXL (>160h)",168,IF(C38="XL (>40h)",48,IF(C38="L (20-40h)",30,IF(C38="M (10-20h)",15,IF(C38="S (<10h)",5,""))))) | J38: =IF($E38="Q12026",COUNTIF($E$3:$E38,"Q12026"),"") | K38: =IF($E38="Q22026",COUNTIF($E$3:$E38,"Q22026"),"") | L38: =IF($E38="Q32026",COUNTIF($E$3:$E38,"Q32026"),"") | M38: =IF($E38="Q42026",COUNTIF($E$3:$E38,"Q42026"),"") | N38: =IF($E38="Backlog",COUNTIF($E$3:$E38,"Backlog"),"")
A39: 37 | H39: =IF(C39="XXL (>160h)",168,IF(C39="XL (>40h)",48,IF(C39="L (20-40h)",30,IF(C39="M (10-20h)",15,IF(C39="S (<10h)",5,""))))) | J39: =IF($E39="Q12026",COUNTIF($E$3:$E39,"Q12026"),"") | K39: =IF($E39="Q22026",COUNTIF($E$3:$E39,"Q22026"),"") | L39: =IF($E39="Q32026",COUNTIF($E$3:$E39,"Q32026"),"") | M39: =IF($E39="Q42026",COUNTIF($E$3:$E39,"Q42026"),"") | N39: =IF($E39="Backlog",COUNTIF($E$3:$E39,"Backlog"),"")
A40: 38 | H40: =IF(C40="XXL (>160h)",168,IF(C40="XL (>40h)",48,IF(C40="L (20-40h)",30,IF(C40="M (10-20h)",15,IF(C40="S (<10h)",5,""))))) | J40: =IF($E40="Q12026",COUNTIF($E$3:$E40,"Q12026"),"") | K40: =IF($E40="Q22026",COUNTIF($E$3:$E40,"Q22026"),"") | L40: =IF($E40="Q32026",COUNTIF($E$3:$E40,"Q32026"),"") | M40: =IF($E40="Q42026",COUNTIF($E$3:$E40,"Q42026"),"") | N40: =IF($E40="Backlog",COUNTIF($E$3:$E40,"Backlog"),"")
...

Sheet Roadmap2026
B1: ENTWICKLUNGS-ROADMAP 2026
B2: Q12026 | F2: Q22026 | J2: Q32026 | N2: Q42026
B3: Kapazität | C3: Stunden | D3: Tage | F3: Kapazität | G3: Stunden | H3: Tage | J3: Kapazität | K3: Stunden | L3: Tage | N3: Kapazität | O3: Stunden | P3: Tage
B4: Gesamt verfügbar | C4: =D4*8 -> 0 | F4: Gesamt verfügbar | G4: =H4*8 -> 0 | J4: Gesamt verfügbar | K4: =L4*8 -> 1192 | L4: 149 | N4: Gesamt verfügbar | O4: =P4*8 -> 0
B5: Team Desktop | C5: =D5*8 -> 0 | F5: Team Desktop | G5: =H5*8 -> 0 | J5: Team Desktop | K5: =L5*8 -> 608 | L5: 76 | N5: Team Desktop | O5: =P5*8 -> 0
B6: Team Web | C6: =D6*8 -> 0 | F6: Team Web | G6: =H6*8 -> 0 | J6: Team Web | K6: =L6*8 -> 688 | L6: 86 | N6: Team Web | O6: =P6*8 -> 0
B7: Grundlast-Verteilung (Ist) | F7: Grundlast-Verteilung (Ist) | J7: Grundlast-Verteilung (Ist) | N7: Grundlast-Verteilung (Ist)
B8: GL-Daily Meetings | D8: =IFERROR(C8/C4,"") | F8: GL-Daily Meetings | H8: =IFERROR(G8/G4,"") | J8: GL-Daily Meetings | L8: =IFERROR(K8/K4,"") -> 0 | N8: GL-Daily Meetings | P8: =IFERROR(O8/O4,"")
B9: GL-Support/Incident | D9: =IFERROR(C9/C4,"") | F9: GL-Support/Incident | H9: =IFERROR(G9/G4,"") | J9: GL-Support/Incident | L9: =IFERROR(K9/K4,"") -> 0 | N9: GL-Support/Incident | P9: =IFERROR(O9/O4,"")
B10: GL-Updates | D10: =IFERROR(C10/C4,"") | F10: GL-Updates | H10: =IFERROR(G10/G4,"") | J10: GL-Updates | L10: =IFERROR(K10/K4,"") -> 0 | N10: GL-Updates | P10: =IFERROR(O10/O4,"")
B11: GL-Verwaltung | D11: =IFERROR(C11/C4,"") | F11: GL-Verwaltung | H11: =IFERROR(G11/G4,"") | J11: GL-Verwaltung | L11: =IFERROR(K11/K4,"") -> 0 | N11: GL-Verwaltung | P11: =IFERROR(O11/O4,"")
B12: GL-Refinement | D12: =IFERROR(C12/C4,"") | F12: GL-Refinement | H12: =IFERROR(G12/G4,"") | J12: GL-Refinement | L12: =IFERROR(K12/K4,"") -> 0 | N12: GL-Refinement | P12: =IFERROR(O12/O4,"")
B13: GL-CodeReview | D13: =IFERROR(C13/C4,"") | F13: GL-CodeReview | H13: =IFERROR(G13/G4,"") | J13: GL-CodeReview | L13: =IFERROR(K13/K4,"") -> 0 | N13: GL-CodeReview | P13: =IFERROR(O13/O4,"")
B14: GL-Technical Debt | D14: =IFERROR(C14/C4,"") | F14: GL-Technical Debt | H14: =IFERROR(G14/G4,"") | J14: GL-Technical Debt | L14: =IFERROR(K14/K4,"") -> 0 | N14: GL-Technical Debt | P14: =IFERROR(O14/O4,"")
B15: GL-Interne Tools | D15: =IFERROR(C15/C4,"") | F15: GL-Interne Tools | H15: =IFERROR(G15/G4,"") | J15: GL-Interne Tools | L15: =IFERROR(K15/K4,"") -> 0 | N15: GL-Interne Tools | P15: =IFERROR(O15/O4,"")
B17: Projekttitel | C17: Größe | D17: Value | F17: Projekttitel | G17: Größe | H17: Value | J17: Projekttitel | K17: Größe | L17: Value | N17: Projekttitel | O17: Größe | P17: Value
F18: =IFERROR(INDEX(DATA2026!B$2:B$401,MATCH(1,DATA2026!J$2:J$401,0)),"") -> Apple iOS SDK Anforderungen | G18: =IFERROR(INDEX(DATA2026!C$2:C$401,MATCH(1,DATA2026!J$2:J$401,0)),"") -> XL (>40h) | H18: =IFERROR(INDEX(DATA2026!D$2:D$401,MATCH(1,DATA2026!J$2:J$401,0)),"") -> Repair | J18: =IFERROR(INDEX(DATA2026!B$2:B$401,MATCH(1,DATA2026!K$2:K$401,0)),"") -> GitHub - Umstellung | K18: =IFERROR(INDEX(DATA2026!C$2:C$401,MATCH(1,DATA2026!K$2:K$401,0)),"") -> L (20-40h) | L18: =IFERROR(INDEX(DATA2026!D$2:D$401,MATCH(1,DATA2026!K$2:K$401,0)),"") -> Strengthen | N18: =IFERROR(INDEX(DATA2026!B$2:B$401,MATCH(1,DATA2026!L$2:L$401,0)),"") -> ReFund Zahlung POS | Refund bei Adyen | Pfand-Gutschrift bei Kartenzahlung | O18: =IFERROR(INDEX(DATA2026!C$2:C$401,MATCH(1,DATA2026!L$2:L$401,0)),"") -> 0 | P18: =IFERROR(INDEX(DATA2026!D$2:D$401,MATCH(1,DATA2026!L$2:L$401,0)),"") -> 0
B19: =IFERROR(INDEX(DATA2026!B$2:B$401,MATCH(2,DATA2026!I$2:I$401,0)),"") | C19: =IFERROR(INDEX(DATA2026!C$2:C$401,MATCH(2,DATA2026!I$2:I$401,0)),"") | D19: =IFERROR(INDEX(DATA2026!D$2:D$401,MATCH(2,DATA2026!I$2:I$401,0)),"") | F19: =IFERROR(INDEX(DATA2026!B$2:B$401,MATCH(2,DATA2026!J$2:J$401,0)),"") -> mobilePeople.de - Vulnerabilitys Portal Live | G19: =IFERROR(INDEX(DATA2026!C$2:C$401,MATCH(2,DATA2026!J$2:J$401,0)),"") -> XL (>40h) | H19: =IFERROR(INDEX(DATA2026!D$2:D$401,MATCH(2,DATA2026!J$2:J$401,0)),"") -> Repair | J19: =IFERROR(INDEX(DATA2026!B$2:B$401,MATCH(2,DATA2026!K$2:K$401,0)),"") -> EFSTA - Anbindung (Spanien) | K19: =IFERROR(INDEX(DATA2026!C$2:C$401,MATCH(2,DATA2026!K$2:K$401,0)),"") -> L (20-40h) | L19: =IFERROR(INDEX(DATA2026!D$2:D$401,MATCH(2,DATA2026!K$2:K$401,0)),"") -> Strengthen | N19: =IFERROR(INDEX(DATA2026!B$2:B$401,MATCH(2,DATA2026!L$2:L$401,0)),"") -> Abholmonitor (ggf. extern) | API | O19: =IFERROR(INDEX(DATA2026!C$2:C$401,MATCH(2,DATA2026!L$2:L$401,0)),"") -> 0 | P19: =IFERROR(INDEX(DATA2026!D$2:D$401,MATCH(2,DATA2026!L$2:L$401,0)),"") -> 0
B20: =IFERROR(INDEX(DATA2026!B$2:B$401,MATCH(3,DATA2026!I$2:I$401,0)),"") | C20: =IFERROR(INDEX(DATA2026!C$2:C$401,MATCH(3,DATA2026!I$2:I$401,0)),"") | D20: =IFERROR(INDEX(DATA2026!D$2:D$401,MATCH(3,DATA2026!I$2:I$401,0)),"") | F20: =IFERROR(INDEX(DATA2026!B$2:B$401,MATCH(3,DATA2026!J$2:J$401,0)),"") -> Webshop mit Newsletter Zustimmung | G20: =IFERROR(INDEX(DATA2026!C$2:C$401,MATCH(3,DATA2026!J$2:J$401,0)),"") -> M (10-20h) | H20: =IFERROR(INDEX(DATA2026!D$2:D$401,MATCH(3,DATA2026!J$2:J$401,0)),"") -> Strengthen | J20: =IFERROR(INDEX(DATA2026!B$2:B$401,MATCH(3,DATA2026!K$2:K$401,0)),"") -> DSFinV-K | Startdatum der ersten Buchung | K20: =IFERROR(INDEX(DATA2026!C$2:C$401,MATCH(3,DATA2026!K$2:K$401,0)),"") -> M (10-20h) | L20: =IFERROR(INDEX(DATA2026!D$2:D$401,MATCH(3,DATA2026!K$2:K$401,0)),"") -> Repair | N20: =IFERROR(INDEX(DATA2026!B$2:B$401,MATCH(3,DATA2026!L$2:L$401,0)),"") -> Portal & POS - UX Update (1) | O20: =IFERROR(INDEX(DATA2026!C$2:C$401,MATCH(3,DATA2026!L$2:L$401,0)),"") -> 0 | P20: =IFERROR(INDEX(DATA2026!D$2:D$401,MATCH(3,DATA2026!L$2:L$401,0)),"") -> 0
B21: =IFERROR(INDEX(DATA2026!B$2:B$401,MATCH(4,DATA2026!I$2:I$401,0)),"") | C21: =IFERROR(INDEX(DATA2026!C$2:C$401,MATCH(4,DATA2026!I$2:I$401,0)),"") | D21: =IFERROR(INDEX(DATA2026!D$2:D$401,MATCH(4,DATA2026!I$2:I$401,0)),"") | F21: =IFERROR(INDEX(DATA2026!B$2:B$401,MATCH(4,DATA2026!J$2:J$401,0)),"") -> Ticketshop mit Kalender & Anzahl | G21: =IFERROR(INDEX(DATA2026!C$2:C$401,MATCH(4,DATA2026!J$2:J$401,0)),"") -> M (10-20h) | H21: =IFERROR(INDEX(DATA2026!D$2:D$401,MATCH(4,DATA2026!J$2:J$401,0)),"") -> Strengthen | J21: =IFERROR(INDEX(DATA2026!B$2:B$401,MATCH(4,DATA2026!K$2:K$401,0)),"") -> Webhook Deliverect | K21: =IFERROR(INDEX(DATA2026!C$2:C$401,MATCH(4,DATA2026!K$2:K$401,0)),"") -> L (20-40h) | L21: =IFERROR(INDEX(DATA2026!D$2:D$401,MATCH(4,DATA2026!K$2:K$401,0)),"") -> Strengthen | N21: =IFERROR(INDEX(DATA2026!B$2:B$401,MATCH(4,DATA2026!L$2:L$401,0)),"") -> Artikelbestandteile im eCom abwählen | O21: =IFERROR(INDEX(DATA2026!C$2:C$401,MATCH(4,DATA2026!L$2:L$401,0)),"") -> 0 | P21: =IFERROR(INDEX(DATA2026!D$2:D$401,MATCH(4,DATA2026!L$2:L$401,0)),"") -> 0
B22: =IFERROR(INDEX(DATA2026!B$2:B$401,MATCH(5,DATA2026!I$2:I$401,0)),"") | C22: =IFERROR(INDEX(DATA2026!C$2:C$401,MATCH(5,DATA2026!I$2:I$401,0)),"") | D22: =IFERROR(INDEX(DATA2026!D$2:D$401,MATCH(5,DATA2026!I$2:I$401,0)),"") | F22: =IFERROR(INDEX(DATA2026!B$2:B$401,MATCH(5,DATA2026!J$2:J$401,0)),"") -> Optimierung SOT Sync | G22: =IFERROR(INDEX(DATA2026!C$2:C$401,MATCH(5,DATA2026!J$2:J$401,0)),"") -> L (20-40h) | H22: =IFERROR(INDEX(DATA2026!D$2:D$401,MATCH(5,DATA2026!J$2:J$401,0)),"") -> Repair | J22: =IFERROR(INDEX(DATA2026!B$2:B$401,MATCH(5,DATA2026!K$2:K$401,0)),"") -> MwSt. Verteilung | K22: =IFERROR(INDEX(DATA2026!C$2:C$401,MATCH(5,DATA2026!K$2:K$401,0)),"") -> XXL (>160h) | L22: =IFERROR(INDEX(DATA2026!D$2:D$401,MATCH(5,DATA2026!K$2:K$401,0)),"") -> Strengthen | N22: =IFERROR(INDEX(DATA2026!B$2:B$401,MATCH(5,DATA2026!L$2:L$401,0)),"") -> KPI Dashboard mit KI | O22: =IFERROR(INDEX(DATA2026!C$2:C$401,MATCH(5,DATA2026!L$2:L$401,0)),"") -> 0 | P22: =IFERROR(INDEX(DATA2026!D$2:D$401,MATCH(5,DATA2026!L$2:L$401,0)),"") -> 0
B23: =IFERROR(INDEX(DATA2026!B$2:B$401,MATCH(6,DATA2026!I$2:I$401,0)),"") | C23: =IFERROR(INDEX(DATA2026!C$2:C$401,MATCH(6,DATA2026!I$2:I$401,0)),"") | D23: =IFERROR(INDEX(DATA2026!D$2:D$401,MATCH(6,DATA2026!I$2:I$401,0)),"") | F23: =IFERROR(INDEX(DATA2026!B$2:B$401,MATCH(6,DATA2026!J$2:J$401,0)),"") -> UHD | AI Agent - Support | G23: =IFERROR(INDEX(DATA2026!C$2:C$401,MATCH(6,DATA2026!J$2:J$401,0)),"") -> L (20-40h) | H23: =IFERROR(INDEX(DATA2026!D$2:D$401,MATCH(6,DATA2026!J$2:J$401,0)),"") -> Strengthen | J23: =IFERROR(INDEX(DATA2026!B$2:B$401,MATCH(6,DATA2026!K$2:K$401,0)),"") -> Protokollierung bei Lizenzzuweisungen. (Internal Audit) | K23: =IFERROR(INDEX(DATA2026!C$2:C$401,MATCH(6,DATA2026!K$2:K$401,0)),"") -> XL (>40h) | L23: =IFERROR(INDEX(DATA2026!D$2:D$401,MATCH(6,DATA2026!K$2:K$401,0)),"") -> Repair | N23: =IFERROR(INDEX(DATA2026!B$2:B$401,MATCH(6,DATA2026!L$2:L$401,0)),"") -> Loyalty (4) | DataWarehouse und KI NOCH NICHT GEPLANT | O23: =IFERROR(INDEX(DATA2026!C$2:C$401,MATCH(6,DATA2026!L$2:L$401,0)),"") -> 0 | P23: =IFERROR(INDEX(DATA2026!D$2:D$401,MATCH(6,DATA2026!L$2:L$401,0)),"") -> 0
B24: =IFERROR(INDEX(DATA2026!B$2:B$401,MATCH(7,DATA2026!I$2:I$401,0)),"") | C24: =IFERROR(INDEX(DATA2026!C$2:C$401,MATCH(7,DATA2026!I$2:I$401,0)),"") | D24: =IFERROR(INDEX(DATA2026!D$2:D$401,MATCH(7,DATA2026!I$2:I$401,0)),"") | F24: =IFERROR(INDEX(DATA2026!B$2:B$401,MATCH(7,DATA2026!J$2:J$401,0)),"") -> 3rd Party - Google Log In für APP | G24: =IFERROR(INDEX(DATA2026!C$2:C$401,MATCH(7,DATA2026!J$2:J$401,0)),"") -> M (10-20h) | H24: =IFERROR(INDEX(DATA2026!D$2:D$401,MATCH(7,DATA2026!J$2:J$401,0)),"") -> Repair | J24: =IFERROR(INDEX(DATA2026!B$2:B$401,MATCH(7,DATA2026!K$2:K$401,0)),"") -> Trinkgeldentnahme signieren (ALEX-GRUPPE) | K24: =IFERROR(INDEX(DATA2026!C$2:C$401,MATCH(7,DATA2026!K$2:K$401,0)),"") -> L (20-40h) | L24: =IFERROR(INDEX(DATA2026!D$2:D$401,MATCH(7,DATA2026!K$2:K$401,0)),"") -> Strengthen | N24: =IFERROR(INDEX(DATA2026!B$2:B$401,MATCH(7,DATA2026!L$2:L$401,0)),"") -> Jouney Gaps (3) | O24: =IFERROR(INDEX(DATA2026!C$2:C$401,MATCH(7,DATA2026!L$2:L$401,0)),"") -> 0 | P24: =IFERROR(INDEX(DATA2026!D$2:D$401,MATCH(7,DATA2026!L$2:L$401,0)),"") -> 0
B25: =IFERROR(INDEX(DATA2026!B$2:B$401,MATCH(8,DATA2026!I$2:I$401,0)),"") | C25: =IFERROR(INDEX(DATA2026!C$2:C$401,MATCH(8,DATA2026!I$2:I$401,0)),"") | D25: =IFERROR(INDEX(DATA2026!D$2:D$401,MATCH(8,DATA2026!I$2:I$401,0)),"") | F25: =IFERROR(INDEX(DATA2026!B$2:B$401,MATCH(8,DATA2026!J$2:J$401,0)),"") -> SIG#156 Landingpage -> Bonuspunkte anzeigen | G25: =IFERROR(INDEX(DATA2026!C$2:C$401,MATCH(8,DATA2026!J$2:J$401,0)),"") -> M (10-20h) | H25: =IFERROR(INDEX(DATA2026!D$2:D$401,MATCH(8,DATA2026!J$2:J$401,0)),"") -> Strengthen | J25: =IFERROR(INDEX(DATA2026!B$2:B$401,MATCH(8,DATA2026!K$2:K$401,0)),"") -> ePOS mobilePRO | K25: =IFERROR(INDEX(DATA2026!C$2:C$401,MATCH(8,DATA2026!K$2:K$401,0)),"") -> XXL (>160h) | L25: =IFERROR(INDEX(DATA2026!D$2:D$401,MATCH(8,DATA2026!K$2:K$401,0)),"") -> Strengthen | N25: =IFERROR(INDEX(DATA2026!B$2:B$401,MATCH(8,DATA2026!L$2:L$401,0)),"") -> Artikelgenaue Übergabe an PMS-Interface (MEWS) | O25: =IFERROR(INDEX(DATA2026!C$2:C$401,MATCH(8,DATA2026!L$2:L$401,0)),"") -> 0 | P25: =IFERROR(INDEX(DATA2026!D$2:D$401,MATCH(8,DATA2026!L$2:L$401,0)),"") -> Strengthen
B26: =IFERROR(INDEX(DATA2026!B$2:B$401,MATCH(9,DATA2026!I$2:I$401,0)),"") | C26: =IFERROR(INDEX(DATA2026!C$2:C$401,MATCH(9,DATA2026!I$2:I$401,0)),"") | D26: =IFERROR(INDEX(DATA2026!D$2:D$401,MATCH(9,DATA2026!I$2:I$401,0)),"") | F26: =IFERROR(INDEX(DATA2026!B$2:B$401,MATCH(9,DATA2026!J$2:J$401,0)),"") -> iCoupon | G26: =IFERROR(INDEX(DATA2026!C$2:C$401,MATCH(9,DATA2026!J$2:J$401,0)),"") -> M (10-20h) | H26: =IFERROR(INDEX(DATA2026!D$2:D$401,MATCH(9,DATA2026!J$2:J$401,0)),"") -> Strengthen | J26: =IFERROR(INDEX(DATA2026!B$2:B$401,MATCH(9,DATA2026!K$2:K$401,0)),"") -> SOT/Webshop & POS | Grundlage / Basis der Kundenkarte QR-Code zur Identifikation | K26: =IFERROR(INDEX(DATA2026!C$2:C$401,MATCH(9,DATA2026!K$2:K$401,0)),"") -> XL (>40h) | L26: =IFERROR(INDEX(DATA2026!D$2:D$401,MATCH(9,DATA2026!K$2:K$401,0)),"") -> Innovation | N26: =IFERROR(INDEX(DATA2026!B$2:B$401,MATCH(9,DATA2026!L$2:L$401,0)),"") -> ePOS Campaigns | O26: =IFERROR(INDEX(DATA2026!C$2:C$401,MATCH(9,DATA2026!L$2:L$401,0)),"") -> 0 | P26: =IFERROR(INDEX(DATA2026!D$2:D$401,MATCH(9,DATA2026!L$2:L$401,0)),"") -> Repair
B27: =IFERROR(INDEX(DATA2026!B$2:B$401,MATCH(10,DATA2026!I$2:I$401,0)),"") | C27: =IFERROR(INDEX(DATA2026!C$2:C$401,MATCH(10,DATA2026!I$2:I$401,0)),"") | D27: =IFERROR(INDEX(DATA2026!D$2:D$401,MATCH(10,DATA2026!I$2:I$401,0)),"") | F27: =IFERROR(INDEX(DATA2026!B$2:B$401,MATCH(10,DATA2026!J$2:J$401,0)),"") -> Supportreduzierung: / Kontingent definieren | G27: =IFERROR(INDEX(DATA2026!C$2:C$401,MATCH(10,DATA2026!J$2:J$401,0)),"") -> XXL (>160h) | H27: =IFERROR(INDEX(DATA2026!D$2:D$401,MATCH(10,DATA2026!J$2:J$401,0)),"") -> Repair | J27: =IFERROR(INDEX(DATA2026!B$2:B$401,MATCH(10,DATA2026!K$2:K$401,0)),"") -> Benefits am SOT einlösen | K27: =IFERROR(INDEX(DATA2026!C$2:C$401,MATCH(10,DATA2026!K$2:K$401,0)),"") -> L (20-40h) | L27: =IFERROR(INDEX(DATA2026!D$2:D$401,MATCH(10,DATA2026!K$2:K$401,0)),"") -> Strengthen | N27: =IFERROR(INDEX(DATA2026!B$2:B$401,MATCH(10,DATA2026!L$2:L$401,0)),"") -> Deaktivierung von Order Channel an POS | O27: =IFERROR(INDEX(DATA2026!C$2:C$401,MATCH(10,DATA2026!L$2:L$401,0)),"") -> 0 | P27: =IFERROR(INDEX(DATA2026!D$2:D$401,MATCH(10,DATA2026!L$2:L$401,0)),"") -> Innovation
B28: =IFERROR(INDEX(DATA2026!B$2:B$401,MATCH(11,DATA2026!I$2:I$401,0)),"") | C28: =IFERROR(INDEX(DATA2026!C$2:C$401,MATCH(11,DATA2026!I$2:I$401,0)),"") | D28: =IFERROR(INDEX(DATA2026!D$2:D$401,MATCH(11,DATA2026!I$2:I$401,0)),"") | F28: =IFERROR(INDEX(DATA2026!B$2:B$401,MATCH(11,DATA2026!J$2:J$401,0)),"") -> Actian Umstellung | G28: =IFERROR(INDEX(DATA2026!C$2:C$401,MATCH(11,DATA2026!J$2:J$401,0)),"") -> XXL (>160h) | H28: =IFERROR(INDEX(DATA2026!D$2:D$401,MATCH(11,DATA2026!J$2:J$401,0)),"") -> Repair | J28: =IFERROR(INDEX(DATA2026!B$2:B$401,MATCH(11,DATA2026!K$2:K$401,0)),"") -> UHD | Rechnungsstellung in CHF | K28: =IFERROR(INDEX(DATA2026!C$2:C$401,MATCH(11,DATA2026!K$2:K$401,0)),"") -> L (20-40h) | L28: =IFERROR(INDEX(DATA2026!D$2:D$401,MATCH(11,DATA2026!K$2:K$401,0)),"") -> Strengthen | N28: =IFERROR(INDEX(DATA2026!B$2:B$401,MATCH(11,DATA2026!L$2:L$401,0)),"") -> Accounting in YourAPP | O28: =IFERROR(INDEX(DATA2026!C$2:C$401,MATCH(11,DATA2026!L$2:L$401,0)),"") -> 0 | P28: =IFERROR(INDEX(DATA2026!D$2:D$401,MATCH(11,DATA2026!L$2:L$401,0)),"") -> Innovation
B29: =IFERROR(INDEX(DATA2026!B$2:B$401,MATCH(12,DATA2026!I$2:I$401,0)),"") | C29: =IFERROR(INDEX(DATA2026!C$2:C$401,MATCH(12,DATA2026!I$2:I$401,0)),"") | D29: =IFERROR(INDEX(DATA2026!D$2:D$401,MATCH(12,DATA2026!I$2:I$401,0)),"") | F29: =IFERROR(INDEX(DATA2026!B$2:B$401,MATCH(12,DATA2026!J$2:J$401,0)),"") -> ePOS mobile PRO V1 | G29: =IFERROR(INDEX(DATA2026!C$2:C$401,MATCH(12,DATA2026!J$2:J$401,0)),"") -> XL (>40h) | H29: =IFERROR(INDEX(DATA2026!D$2:D$401,MATCH(12,DATA2026!J$2:J$401,0)),"") -> Innovation | J29: =IFERROR(INDEX(DATA2026!B$2:B$401,MATCH(12,DATA2026!K$2:K$401,0)),"") -> UHD | Filtermöglichkeit für „Priorisierung“ | K29: =IFERROR(INDEX(DATA2026!C$2:C$401,MATCH(12,DATA2026!K$2:K$401,0)),"") -> L (20-40h) | L29: =IFERROR(INDEX(DATA2026!D$2:D$401,MATCH(12,DATA2026!K$2:K$401,0)),"") -> Strengthen | N29: =IFERROR(INDEX(DATA2026!B$2:B$401,MATCH(12,DATA2026!L$2:L$401,0)),"") -> Signum Orga-Soft API erweitern | O29: =IFERROR(INDEX(DATA2026!C$2:C$401,MATCH(12,DATA2026!L$2:L$401,0)),"") -> 0 | P29: =IFERROR(INDEX(DATA2026!D$2:D$401,MATCH(12,DATA2026!L$2:L$401,0)),"") -> Strengthen
B30: =IFERROR(INDEX(DATA2026!B$2:B$401,MATCH(13,DATA2026!I$2:I$401,0)),"") | C30: =IFERROR(INDEX(DATA2026!C$2:C$401,MATCH(13,DATA2026!I$2:I$401,0)),"") | D30: =IFERROR(INDEX(DATA2026!D$2:D$401,MATCH(13,DATA2026!I$2:I$401,0)),"") | F30: =IFERROR(INDEX(DATA2026!B$2:B$401,MATCH(13,DATA2026!J$2:J$401,0)),"") -> Artikel-Tabellenbearbeitung auch Bilder (Shop) hinzufügen | G30: =IFERROR(INDEX(DATA2026!C$2:C$401,MATCH(13,DATA2026!J$2:J$401,0)),"") -> M (10-20h) | H30: =IFERROR(INDEX(DATA2026!D$2:D$401,MATCH(13,DATA2026!J$2:J$401,0)),"") -> Strengthen | J30: =IFERROR(INDEX(DATA2026!B$2:B$401,MATCH(13,DATA2026!K$2:K$401,0)),"") -> UHD | Bearbeiter ergänzen / anzeigen | K30: =IFERROR(INDEX(DATA2026!C$2:C$401,MATCH(13,DATA2026!K$2:K$401,0)),"") -> L (20-40h) | L30: =IFERROR(INDEX(DATA2026!D$2:D$401,MATCH(13,DATA2026!K$2:K$401,0)),"") -> Strengthen | N30: =IFERROR(INDEX(DATA2026!B$2:B$401,MATCH(13,DATA2026!L$2:L$401,0)),"") -> Loyalty (3) | Couopons 2.0 NOCH NICHT GEPLANT | O30: =IFERROR(INDEX(DATA2026!C$2:C$401,MATCH(13,DATA2026!L$2:L$401,0)),"") -> 0 | P30: =IFERROR(INDEX(DATA2026!D$2:D$401,MATCH(13,DATA2026!L$2:L$401,0)),"") -> Innovation
B31: =IFERROR(INDEX(DATA2026!B$2:B$401,MATCH(14,DATA2026!I$2:I$401,0)),"") | C31: =IFERROR(INDEX(DATA2026!C$2:C$401,MATCH(14,DATA2026!I$2:I$401,0)),"") | D31: =IFERROR(INDEX(DATA2026!D$2:D$401,MATCH(14,DATA2026!I$2:I$401,0)),"") | F31: =IFERROR(INDEX(DATA2026!B$2:B$401,MATCH(14,DATA2026!J$2:J$401,0)),"") -> DSFinV-K: Verknüpfung von Bestellsignaturen | G31: =IFERROR(INDEX(DATA2026!C$2:C$401,MATCH(14,DATA2026!J$2:J$401,0)),"") -> L (20-40h) | H31: =IFERROR(INDEX(DATA2026!D$2:D$401,MATCH(14,DATA2026!J$2:J$401,0)),"") -> Strengthen | J31: =IFERROR(INDEX(DATA2026!B$2:B$401,MATCH(14,DATA2026!K$2:K$401,0)),"") -> UHD | S, M, L im UH sichtbar/Filterbar. (Kritisch, Wichtig und Normal -> sichtbar) | K31: =IFERROR(INDEX(DATA2026!C$2:C$401,MATCH(14,DATA2026!K$2:K$401,0)),"") -> L (20-40h) | L31: =IFERROR(INDEX(DATA2026!D$2:D$401,MATCH(14,DATA2026!K$2:K$401,0)),"") -> Strengthen | N31: =IFERROR(INDEX(DATA2026!B$2:B$401,MATCH(14,DATA2026!L$2:L$401,0)),"") -> Data Warehouse | O31: =IFERROR(INDEX(DATA2026!C$2:C$401,MATCH(14,DATA2026!L$2:L$401,0)),"") -> 0 | P31: =IFERROR(INDEX(DATA2026!D$2:D$401,MATCH(14,DATA2026!L$2:L$401,0)),"") -> Strengthen
B32: =IFERROR(INDEX(DATA2026!B$2:B$401,MATCH(15,DATA2026!I$2:I$401,0)),"") | C32: =IFERROR(INDEX(DATA2026!C$2:C$401,MATCH(15,DATA2026!I$2:I$401,0)),"") | D32: =IFERROR(INDEX(DATA2026!D$2:D$401,MATCH(15,DATA2026!I$2:I$401,0)),"") | F32: =IFERROR(INDEX(DATA2026!B$2:B$401,MATCH(15,DATA2026!J$2:J$401,0)),"") | G32: =IFERROR(INDEX(DATA2026!C$2:C$401,MATCH(15,DATA2026!J$2:J$401,0)),"") | H32: =IFERROR(INDEX(DATA2026!D$2:D$401,MATCH(15,DATA2026!J$2:J$401,0)),"") | J32: =IFERROR(INDEX(DATA2026!B$2:B$401,MATCH(15,DATA2026!K$2:K$401,0)),"") -> Loaylty | Bonussystem 2.0 | K32: =IFERROR(INDEX(DATA2026!C$2:C$401,MATCH(15,DATA2026!K$2:K$401,0)),"") -> XXL (>160h) | L32: =IFERROR(INDEX(DATA2026!D$2:D$401,MATCH(15,DATA2026!K$2:K$401,0)),"") -> Innovation | N32: =IFERROR(INDEX(DATA2026!B$2:B$401,MATCH(15,DATA2026!L$2:L$401,0)),"") -> Paypal V2 | O32: =IFERROR(INDEX(DATA2026!C$2:C$401,MATCH(15,DATA2026!L$2:L$401,0)),"") -> 0 | P32: =IFERROR(INDEX(DATA2026!D$2:D$401,MATCH(15,DATA2026!L$2:L$401,0)),"") -> Strengthen
B33: =IFERROR(INDEX(DATA2026!B$2:B$401,MATCH(16,DATA2026!I$2:I$401,0)),"") | C33: =IFERROR(INDEX(DATA2026!C$2:C$401,MATCH(16,DATA2026!I$2:I$401,0)),"") | D33: =IFERROR(INDEX(DATA2026!D$2:D$401,MATCH(16,DATA2026!I$2:I$401,0)),"") | F33: =IFERROR(INDEX(DATA2026!B$2:B$401,MATCH(16,DATA2026!J$2:J$401,0)),"") | G33: =IFERROR(INDEX(DATA2026!C$2:C$401,MATCH(16,DATA2026!J$2:J$401,0)),"") | H33: =IFERROR(INDEX(DATA2026!D$2:D$401,MATCH(16,DATA2026!J$2:J$401,0)),"") | J33: =IFERROR(INDEX(DATA2026!B$2:B$401,MATCH(16,DATA2026!K$2:K$401,0)),"") -> Wallet-Anbindung iOS & Android | Web Gutscheine und Tickets | K33: =IFERROR(INDEX(DATA2026!C$2:C$401,MATCH(16,DATA2026!K$2:K$401,0)),"") -> XL (>40h) | L33: =IFERROR(INDEX(DATA2026!D$2:D$401,MATCH(16,DATA2026!K$2:K$401,0)),"") -> Innovation | N33: =IFERROR(INDEX(DATA2026!B$2:B$401,MATCH(16,DATA2026!L$2:L$401,0)),"") -> App-Systemstart beschleunigen / Code aktualisieren | O33: =IFERROR(INDEX(DATA2026!C$2:C$401,MATCH(16,DATA2026!L$2:L$401,0)),"") -> 0 | P33: =IFERROR(INDEX(DATA2026!D$2:D$401,MATCH(16,DATA2026!L$2:L$401,0)),"") -> Strengthen
B34: =IFERROR(INDEX(DATA2026!B$2:B$401,MATCH(17,DATA2026!I$2:I$401,0)),"") | C34: =IFERROR(INDEX(DATA2026!C$2:C$401,MATCH(17,DATA2026!I$2:I$401,0)),"") | D34: =IFERROR(INDEX(DATA2026!D$2:D$401,MATCH(17,DATA2026!I$2:I$401,0)),"") | F34: =IFERROR(INDEX(DATA2026!B$2:B$401,MATCH(17,DATA2026!J$2:J$401,0)),"") | G34: =IFERROR(INDEX(DATA2026!C$2:C$401,MATCH(17,DATA2026!J$2:J$401,0)),"") | H34: =IFERROR(INDEX(DATA2026!D$2:D$401,MATCH(17,DATA2026!J$2:J$401,0)),"") | J34: =IFERROR(INDEX(DATA2026!B$2:B$401,MATCH(17,DATA2026!K$2:K$401,0)),"") -> API | Externer Kundenstamm | K34: =IFERROR(INDEX(DATA2026!C$2:C$401,MATCH(17,DATA2026!K$2:K$401,0)),"") -> L (20-40h) | L34: =IFERROR(INDEX(DATA2026!D$2:D$401,MATCH(17,DATA2026!K$2:K$401,0)),"") -> Strengthen | N34: =IFERROR(INDEX(DATA2026!B$2:B$401,MATCH(17,DATA2026!L$2:L$401,0)),"") -> SIG - WAWI - Schnittstelle (Foodnotify / Apicbase) -> CDS & Vapiano | O34: =IFERROR(INDEX(DATA2026!C$2:C$401,MATCH(17,DATA2026!L$2:L$401,0)),"") -> 0 | P34: =IFERROR(INDEX(DATA2026!D$2:D$401,MATCH(17,DATA2026!L$2:L$401,0)),"") -> Innovation
B35: =IFERROR(INDEX(DATA2026!B$2:B$401,MATCH(18,DATA2026!I$2:I$401,0)),"") | C35: =IFERROR(INDEX(DATA2026!C$2:C$401,MATCH(18,DATA2026!I$2:I$401,0)),"") | D35: =IFERROR(INDEX(DATA2026!D$2:D$401,MATCH(18,DATA2026!I$2:I$401,0)),"") | F35: =IFERROR(INDEX(DATA2026!B$2:B$401,MATCH(18,DATA2026!J$2:J$401,0)),"") | G35: =IFERROR(INDEX(DATA2026!C$2:C$401,MATCH(18,DATA2026!J$2:J$401,0)),"") | H35: =IFERROR(INDEX(DATA2026!D$2:D$401,MATCH(18,DATA2026!J$2:J$401,0)),"") | J35: =IFERROR(INDEX(DATA2026!B$2:B$401,MATCH(18,DATA2026!K$2:K$401,0)),"") -> TWINT / Konstantin / HILTL | K35: =IFERROR(INDEX(DATA2026!C$2:C$401,MATCH(18,DATA2026!K$2:K$401,0)),"") -> M (10-20h) | L35: =IFERROR(INDEX(DATA2026!D$2:D$401,MATCH(18,DATA2026!K$2:K$401,0)),"") -> Repair | N35: =IFERROR(INDEX(DATA2026!B$2:B$401,MATCH(18,DATA2026!L$2:L$401,0)),"") -> NoCOO Code am SOT mit optionalem Ausdruck / weitere Informationen müssen ergänzt werden (Superhelden, etc.) -> Bewerten Q3 | O35: =IFERROR(INDEX(DATA2026!C$2:C$401,MATCH(18,DATA2026!L$2:L$401,0)),"") -> 0 | P35: =IFERROR(INDEX(DATA2026!D$2:D$401,MATCH(18,DATA2026!L$2:L$401,0)),"") -> Strengthen
B36: =IFERROR(INDEX(DATA2026!B$2:B$401,MATCH(19,DATA2026!I$2:I$401,0)),"") | C36: =IFERROR(INDEX(DATA2026!C$2:C$401,MATCH(19,DATA2026!I$2:I$401,0)),"") | D36: =IFERROR(INDEX(DATA2026!D$2:D$401,MATCH(19,DATA2026!I$2:I$401,0)),"") | F36: =IFERROR(INDEX(DATA2026!B$2:B$401,MATCH(19,DATA2026!J$2:J$401,0)),"") | G36: =IFERROR(INDEX(DATA2026!C$2:C$401,MATCH(19,DATA2026!J$2:J$401,0)),"") | H36: =IFERROR(INDEX(DATA2026!D$2:D$401,MATCH(19,DATA2026!J$2:J$401,0)),"") | J36: =IFERROR(INDEX(DATA2026!B$2:B$401,MATCH(19,DATA2026!K$2:K$401,0)),"") -> OpenTable API | K36: =IFERROR(INDEX(DATA2026!C$2:C$401,MATCH(19,DATA2026!K$2:K$401,0)),"") -> M (10-20h) | L36: =IFERROR(INDEX(DATA2026!D$2:D$401,MATCH(19,DATA2026!K$2:K$401,0)),"") -> Innovation | N36: =IFERROR(INDEX(DATA2026!B$2:B$401,MATCH(19,DATA2026!L$2:L$401,0)),"") -> Borland Code Migrieren in Visual Studio - bis Q4 muss das umgesetzt werden | O36: =IFERROR(INDEX(DATA2026!C$2:C$401,MATCH(19,DATA2026!L$2:L$401,0)),"") -> 0 | P36: =IFERROR(INDEX(DATA2026!D$2:D$401,MATCH(19,DATA2026!L$2:L$401,0)),"") -> Strengthen
B37: =IFERROR(INDEX(DATA2026!B$2:B$401,MATCH(20,DATA2026!I$2:I$401,0)),"") | C37: =IFERROR(INDEX(DATA2026!C$2:C$401,MATCH(20,DATA2026!I$2:I$401,0)),"") | D37: =IFERROR(INDEX(DATA2026!D$2:D$401,MATCH(20,DATA2026!I$2:I$401,0)),"") | F37: =IFERROR(INDEX(DATA2026!B$2:B$401,MATCH(20,DATA2026!J$2:J$401,0)),"") | G37: =IFERROR(INDEX(DATA2026!C$2:C$401,MATCH(20,DATA2026!J$2:J$401,0)),"") | H37: =IFERROR(INDEX(DATA2026!D$2:D$401,MATCH(20,DATA2026!J$2:J$401,0)),"") | J37: =IFERROR(INDEX(DATA2026!B$2:B$401,MATCH(20,DATA2026!K$2:K$401,0)),"") -> UHD | Incident Feedback an Kunde | K37: =IFERROR(INDEX(DATA2026!C$2:C$401,MATCH(20,DATA2026!K$2:K$401,0)),"") -> L (20-40h) | L37: =IFERROR(INDEX(DATA2026!D$2:D$401,MATCH(20,DATA2026!K$2:K$401,0)),"") -> Strengthen | N37: =IFERROR(INDEX(DATA2026!B$2:B$401,MATCH(20,DATA2026!L$2:L$401,0)),"") -> 64 Bit Konvertierung | O37: =IFERROR(INDEX(DATA2026!C$2:C$401,MATCH(20,DATA2026!L$2:L$401,0)),"") -> 0 | P37: =IFERROR(INDEX(DATA2026!D$2:D$401,MATCH(20,DATA2026!L$2:L$401,0)),"") -> Strengthen
B38: =IFERROR(INDEX(DATA2026!B$2:B$401,MATCH(21,DATA2026!I$2:I$401,0)),"") | C38: =IFERROR(INDEX(DATA2026!C$2:C$401,MATCH(21,DATA2026!I$2:I$401,0)),"") | D38: =IFERROR(INDEX(DATA2026!D$2:D$401,MATCH(21,DATA2026!I$2:I$401,0)),"") | F38: =IFERROR(INDEX(DATA2026!B$2:B$401,MATCH(21,DATA2026!J$2:J$401,0)),"") | G38: =IFERROR(INDEX(DATA2026!C$2:C$401,MATCH(21,DATA2026!J$2:J$401,0)),"") | H38: =IFERROR(INDEX(DATA2026!D$2:D$401,MATCH(21,DATA2026!J$2:J$401,0)),"") | J38: =IFERROR(INDEX(DATA2026!B$2:B$401,MATCH(21,DATA2026!K$2:K$401,0)),"") -> HeyRosi -> API | K38: =IFERROR(INDEX(DATA2026!C$2:C$401,MATCH(21,DATA2026!K$2:K$401,0)),"") -> M (10-20h) | L38: =IFERROR(INDEX(DATA2026!D$2:D$401,MATCH(21,DATA2026!K$2:K$401,0)),"") -> Innovation | N38: =IFERROR(INDEX(DATA2026!B$2:B$401,MATCH(21,DATA2026!L$2:L$401,0)),"") -> Webshop und erweiterte Zeitsteuerung (Artikel nicht verfügbar, bei Bestellung morgens für Mittags) -> CDS | O38: =IFERROR(INDEX(DATA2026!C$2:C$401,MATCH(21,DATA2026!L$2:L$401,0)),"") -> 0 | P38: =IFERROR(INDEX(DATA2026!D$2:D$401,MATCH(21,DATA2026!L$2:L$401,0)),"") -> Strengthen
B39: =IFERROR(INDEX(DATA2026!B$2:B$401,MATCH(22,DATA2026!I$2:I$401,0)),"") | C39: =IFERROR(INDEX(DATA2026!C$2:C$401,MATCH(22,DATA2026!I$2:I$401,0)),"") | D39: =IFERROR(INDEX(DATA2026!D$2:D$401,MATCH(22,DATA2026!I$2:I$401,0)),"") | F39: =IFERROR(INDEX(DATA2026!B$2:B$401,MATCH(22,DATA2026!J$2:J$401,0)),"") | G39: =IFERROR(INDEX(DATA2026!C$2:C$401,MATCH(22,DATA2026!J$2:J$401,0)),"") | H39: =IFERROR(INDEX(DATA2026!D$2:D$401,MATCH(22,DATA2026!J$2:J$401,0)),"") | J39: =IFERROR(INDEX(DATA2026!B$2:B$401,MATCH(22,DATA2026!K$2:K$401,0)),"") -> Landingpage zur Registrierung | K39: =IFERROR(INDEX(DATA2026!C$2:C$401,MATCH(22,DATA2026!K$2:K$401,0)),"") -> M (10-20h) | L39: =IFERROR(INDEX(DATA2026!D$2:D$401,MATCH(22,DATA2026!K$2:K$401,0)),"") -> Strengthen | N39: =IFERROR(INDEX(DATA2026!B$2:B$401,MATCH(22,DATA2026!L$2:L$401,0)),"") -> Digital Signage (Api) | O39: =IFERROR(INDEX(DATA2026!C$2:C$401,MATCH(22,DATA2026!L$2:L$401,0)),"") -> 0 | P39: =IFERROR(INDEX(DATA2026!D$2:D$401,MATCH(22,DATA2026!L$2:L$401,0)),"") -> Innovation
B40: =IFERROR(INDEX(DATA2026!B$2:B$401,MATCH(23,DATA2026!I$2:I$401,0)),"") | C40: =IFERROR(INDEX(DATA2026!C$2:C$401,MATCH(23,DATA2026!I$2:I$401,0)),"") | D40: =IFERROR(INDEX(DATA2026!D$2:D$401,MATCH(23,DATA2026!I$2:I$401,0)),"") | F40: =IFERROR(INDEX(DATA2026!B$2:B$401,MATCH(23,DATA2026!J$2:J$401,0)),"") | G40: =IFERROR(INDEX(DATA2026!C$2:C$401,MATCH(23,DATA2026!J$2:J$401,0)),"") | H40: =IFERROR(INDEX(DATA2026!D$2:D$401,MATCH(23,DATA2026!J$2:J$401,0)),"") | J40: =IFERROR(INDEX(DATA2026!B$2:B$401,MATCH(23,DATA2026!K$2:K$401,0)),"") -> UI / Code - Portalmodernisierung | Benutzer | K40: =IFERROR(INDEX(DATA2026!C$2:C$401,MATCH(23,DATA2026!K$2:K$401,0)),"") -> XXL (>160h) | L40: =IFERROR(INDEX(DATA2026!D$2:D$401,MATCH(23,DATA2026!K$2:K$401,0)),"") -> Strengthen | N40: =IFERROR(INDEX(DATA2026!B$2:B$401,MATCH(23,DATA2026!L$2:L$401,0)),"") -> 2-Faktor-Authentifizierung / Portal | O40: =IFERROR(INDEX(DATA2026!C$2:C$401,MATCH(23,DATA2026!L$2:L$401,0)),"") -> 0 | P40: =IFERROR(INDEX(DATA2026!D$2:D$401,MATCH(23,DATA2026!L$2:L$401,0)),"") -> Strengthen
B41: =IFERROR(INDEX(DATA2026!B$2:B$401,MATCH(24,DATA2026!I$2:I$401,0)),"") | C41: =IFERROR(INDEX(DATA2026!C$2:C$401,MATCH(24,DATA2026!I$2:I$401,0)),"") | D41: =IFERROR(INDEX(DATA2026!D$2:D$401,MATCH(24,DATA2026!I$2:I$401,0)),"") | F41: =IFERROR(INDEX(DATA2026!B$2:B$401,MATCH(24,DATA2026!J$2:J$401,0)),"") | G41: =IFERROR(INDEX(DATA2026!C$2:C$401,MATCH(24,DATA2026!J$2:J$401,0)),"") | H41: =IFERROR(INDEX(DATA2026!D$2:D$401,MATCH(24,DATA2026!J$2:J$401,0)),"") | J41: =IFERROR(INDEX(DATA2026!B$2:B$401,MATCH(24,DATA2026!K$2:K$401,0)),"") -> Einmal einlösbare Coupons für die YourApp | K41: =IFERROR(INDEX(DATA2026!C$2:C$401,MATCH(24,DATA2026!K$2:K$401,0)),"") -> XL (>40h) | L41: =IFERROR(INDEX(DATA2026!D$2:D$401,MATCH(24,DATA2026!K$2:K$401,0)),"") -> Strengthen | N41: =IFERROR(INDEX(DATA2026!B$2:B$401,MATCH(24,DATA2026!L$2:L$401,0)),"") -> UHD - RMA Digitalisieren | O41: =IFERROR(INDEX(DATA2026!C$2:C$401,MATCH(24,DATA2026!L$2:L$401,0)),"") -> 0 | P41: =IFERROR(INDEX(DATA2026!D$2:D$401,MATCH(24,DATA2026!L$2:L$401,0)),"") -> Strengthen
...

Sheet Dashboard2026
A1: DASHBOARD — Roadmap 2026
A3: VALUE-BUCKET VERTEILUNG — Anzahl & Prozent
B4: Q1 | C4: Q2 | D4: Q3 | E4: Q4 | F4: Gesamt Jahr
A5: Strengthen (Anzahl) | B5: =COUNTIFS(DATA2026!A$2:A$401,"Q12026",DATA2026!D$2:D$401,"Strengthen") -> 0 | C5: =COUNTIFS(DATA2026!A$2:A$401,"Q22026",DATA2026!D$2:D$401,"Strengthen") -> 7 | D5: =COUNTIFS(DATA2026!A$2:A$401,"Q32026",DATA2026!D$2:D$401,"Strengthen") -> 16 | E5: =COUNTIFS(DATA2026!A$2:A$401,"Q42026",DATA2026!D$2:D$401,"Strengthen") -> 11 | F5: =COUNTIF(DATA2026!D$2:D$401,"Strengthen") -> 34
A6: Strengthen (%) | B6: =IFERROR(B5/B11,"") | C6: =IFERROR(C5/C11,"") -> 0.5 | D6: =IFERROR(D5/D11,"") -> 0.66666667 | E6: =IFERROR(E5/E11,"") -> 0.64705882 | F6: =IFERROR(F5/F11,"") -> 0.61818182
A7: Innovation (Anzahl) | B7: =COUNTIFS(DATA2026!A$2:A$401,"Q12026",DATA2026!D$2:D$401,"Innovation") -> 0 | C7: =COUNTIFS(DATA2026!A$2:A$401,"Q22026",DATA2026!D$2:D$401,"Innovation") -> 1 | D7: =COUNTIFS(DATA2026!A$2:A$401,"Q32026",DATA2026!D$2:D$401,"Innovation") -> 5 | E7: =COUNTIFS(DATA2026!A$2:A$401,"Q42026",DATA2026!D$2:D$401,"Innovation") -> 5 | F7: =COUNTIF(DATA2026!D$2:D$401,"Innovation") -> 11
A8: Innovation (%) | B8: =IFERROR(B7/B11,"") | C8: =IFERROR(C7/C11,"") -> 0.071428571 | D8: =IFERROR(D7/D11,"") -> 0.20833333 | E8: =IFERROR(E7/E11,"") -> 0.29411765 | F8: =IFERROR(F7/F11,"") -> 0.2
A9: Repair (Anzahl) | B9: =COUNTIFS(DATA2026!A$2:A$401,"Q12026",DATA2026!D$2:D$401,"Repair") -> 0 | C9: =COUNTIFS(DATA2026!A$2:A$401,"Q22026",DATA2026!D$2:D$401,"Repair") -> 6 | D9: =COUNTIFS(DATA2026!A$2:A$401,"Q32026",DATA2026!D$2:D$401,"Repair") -> 3 | E9: =COUNTIFS(DATA2026!A$2:A$401,"Q42026",DATA2026!D$2:D$401,"Repair") -> 1 | F9: =COUNTIF(DATA2026!D$2:D$401,"Repair") -> 10
A10: Repair (%) | B10: =IFERROR(B9/B11,"") | C10: =IFERROR(C9/C11,"") -> 0.42857143 | D10: =IFERROR(D9/D11,"") -> 0.125 | E10: =IFERROR(E9/E11,"") -> 0.058823529 | F10: =IFERROR(F9/F11,"") -> 0.18181818
A11: Gesamt Projekte | B11: =B5+B7+B9 -> 0 | C11: =C5+C7+C9 -> 14 | D11: =D5+D7+D9 -> 24 | E11: =E5+E7+E9 -> 17 | F11: =F5+F7+F9 -> 55
A14: KAPAZITÄT vs. GEPLANTE STUNDEN — pro Quartal & Team
B15: Q1 | C15: Q2 | D15: Q3 | E15: Q4
A16: Kapazität Gesamt (h) | B16: =Roadmap2026!C4 -> 0 | C16: =Roadmap2026!G4 -> 0 | D16: =Roadmap2026!K4 -> 1192 | E16: =Roadmap2026!O4 -> 0
A17: → Team Desktop (h) | B17: =Roadmap2026!C5 -> 0 | C17: =Roadmap2026!G5 -> 0 | D17: =Roadmap2026!K5 -> 608 | E17: =Roadmap2026!O5 -> 0
A18: → Team Web (h) | B18: =Roadmap2026!C6 -> 0 | C18: =Roadmap2026!G6 -> 0 | D18: =Roadmap2026!K6 -> 688 | E18: =Roadmap2026!O6 -> 0
A19: Geplant Gesamt (h) | B19: =SUMIF(DATA2026!A$2:A$401,"Q12026",DATA2026!E$2:E$401) -> 0 | C19: =SUMIF(DATA2026!A$2:A$401,"Q22026",DATA2026!E$2:E$401) -> 660 | D19: =SUMIF(DATA2026!A$2:A$401,"Q32026",DATA2026!E$2:E$401) -> 1269 | E19: =SUMIF(DATA2026!A$2:A$401,"Q42026",DATA2026!E$2:E$401) -> 0
A20: → Desktop geplant (h) | B20: =SUMIFS(DATA2026!E$2:E$401,DATA2026!A$2:A$401,"Q12026",DATA2026!G$2:G$401,"Desktop") -> 0 | C20: =SUMIFS(DATA2026!E$2:E$401,DATA2026!A$2:A$401,"Q22026",DATA2026!G$2:G$401,"Desktop") -> 444 | D20: =SUMIFS(DATA2026!E$2:E$401,DATA2026!A$2:A$401,"Q32026",DATA2026!G$2:G$401,"Desktop") -> 489 | E20: =SUMIFS(DATA2026!E$2:E$401,DATA2026!A$2:A$401,"Q42026",DATA2026!G$2:G$401,"Desktop") -> 0
A21: → Web geplant (h) | B21: =SUMIFS(DATA2026!E$2:E$401,DATA2026!A$2:A$401,"Q12026",DATA2026!G$2:G$401,"WEB") -> 0 | C21: =SUMIFS(DATA2026!E$2:E$401,DATA2026!A$2:A$401,"Q22026",DATA2026!G$2:G$401,"WEB") -> 216 | D21: =SUMIFS(DATA2026!E$2:E$401,DATA2026!A$2:A$401,"Q32026",DATA2026!G$2:G$401,"WEB") -> 672 | E21: =SUMIFS(DATA2026!E$2:E$401,DATA2026!A$2:A$401,"Q42026",DATA2026!G$2:G$401,"WEB") -> 0
A22: → W->D anteilig (h) | B22: =SUMIFS(DATA2026!E$2:E$401,DATA2026!A$2:A$401,"Q12026",DATA2026!G$2:G$401,"W->D")*0.5 -> 0 | C22: =SUMIFS(DATA2026!E$2:E$401,DATA2026!A$2:A$401,"Q22026",DATA2026!G$2:G$401,"W->D")*0.5 -> 0 | D22: =SUMIFS(DATA2026!E$2:E$401,DATA2026!A$2:A$401,"Q32026",DATA2026!G$2:G$401,"W->D")*0.5 -> 39 | E22: =SUMIFS(DATA2026!E$2:E$401,DATA2026!A$2:A$401,"Q42026",DATA2026!G$2:G$401,"W->D")*0.5 -> 0
A23: → D->W anteilig (h) | B23: =SUMIFS(DATA2026!E$2:E$401,DATA2026!A$2:A$401,"Q12026",DATA2026!G$2:G$401,"D->W")*0.5 -> 0 | C23: =SUMIFS(DATA2026!E$2:E$401,DATA2026!A$2:A$401,"Q22026",DATA2026!G$2:G$401,"D->W")*0.5 -> 0 | D23: =SUMIFS(DATA2026!E$2:E$401,DATA2026!A$2:A$401,"Q32026",DATA2026!G$2:G$401,"D->W")*0.5 -> 15 | E23: =SUMIFS(DATA2026!E$2:E$401,DATA2026!A$2:A$401,"Q42026",DATA2026!G$2:G$401,"D->W")*0.5 -> 0
A24: Effektiv Desktop (h) | B24: =B20+B22+B23 -> 0 | C24: =C20+C22+C23 -> 444 | D24: =D20+D22+D23 -> 543 | E24: =E20+E22+E23 -> 0
A25: Effektiv Web (h) | B25: =B21+B22+B23 -> 0 | C25: =C21+C22+C23 -> 216 | D25: =D21+D22+D23 -> 726 | E25: =E21+E22+E23 -> 0
A26: Auslastung Desktop % | B26: =IFERROR(B24/B17,"") | C26: =IFERROR(C24/C17,"") | D26: =IFERROR(D24/D17,"") -> 0.89309211 | E26: =IFERROR(E24/E17,"")
A27: Auslastung Web % | B27: =IFERROR(B26/B18,"") | C27: =IFERROR(C26/C18,"") | D27: =IFERROR(D25/D18,"") -> 1.0552326 | E27: =IFERROR(E26/E18,"")
A30: MoSCoW VERTEILUNG — pro Quartal
B31: Q1 | C31: Q2 | D31: Q3 | E31: Q4 | F31: Gesamt
A32: Must | B32: =COUNTIFS(DATA2026!A$2:A$401,"Q12026",DATA2026!F$2:F$401,"Must") -> 0 | C32: =COUNTIFS(DATA2026!A$2:A$401,"Q22026",DATA2026!F$2:F$401,"Must") -> 11 | D32: =COUNTIFS(DATA2026!A$2:A$401,"Q32026",DATA2026!F$2:F$401,"Must") -> 12 | E32: =COUNTIFS(DATA2026!A$2:A$401,"Q42026",DATA2026!F$2:F$401,"Must") -> 1 | F32: =COUNTIF(DATA2026!F$2:F$401,"Must") -> 24
A33: Should | B33: =COUNTIFS(DATA2026!A$2:A$401,"Q12026",DATA2026!F$2:F$401,"Should") -> 0 | C33: =COUNTIFS(DATA2026!A$2:A$401,"Q22026",DATA2026!F$2:F$401,"Should") -> 2 | D33: =COUNTIFS(DATA2026!A$2:A$401,"Q32026",DATA2026!F$2:F$401,"Should") -> 10 | E33: =COUNTIFS(DATA2026!A$2:A$401,"Q42026",DATA2026!F$2:F$401,"Should") -> 3 | F33: =COUNTIF(DATA2026!F$2:F$401,"Should") -> 15
A34: Could | B34: =COUNTIFS(DATA2026!A$2:A$401,"Q12026",DATA2026!F$2:F$401,"Could") -> 0 | C34: =COUNTIFS(DATA2026!A$2:A$401,"Q22026",DATA2026!F$2:F$401,"Could") -> 1 | D34: =COUNTIFS(DATA2026!A$2:A$401,"Q32026",DATA2026!F$2:F$401,"Could") -> 2 | E34: =COUNTIFS(DATA2026!A$2:A$401,"Q42026",DATA2026!F$2:F$401,"Could") -> 1 | F34: =COUNTIF(DATA2026!F$2:F$401,"Could") -> 4
A35: Won't | B35: =COUNTIFS(DATA2026!A$2:A$401,"Q12026",DATA2026!F$2:F$401,"Won't") -> 0 | C35: =COUNTIFS(DATA2026!A$2:A$401,"Q22026",DATA2026!F$2:F$401,"Won't") -> 0 | D35: =COUNTIFS(DATA2026!A$2:A$401,"Q32026",DATA2026!F$2:F$401,"Won't") -> 0 | E35: =COUNTIFS(DATA2026!A$2:A$401,"Q42026",DATA2026!F$2:F$401,"Won't") -> 0 | F35: =COUNTIF(DATA2026!F$2:F$401,"Won't") -> 0
A37: TEAM-ZUWEISUNG — Stunden pro Quartal
A38: Team | B38: Q1 | C38: Q2 | D38: Q3 | E38: Q4 | F38: Gesamt
A39: WEB | B39: =SUMIFS(DATA2026!E$2:E$401,DATA2026!A$2:A$401,"Q12026",DATA2026!G$2:G$401,"WEB") -> 0 | C39: =SUMIFS(DATA2026!E$2:E$401,DATA2026!A$2:A$401,"Q22026",DATA2026!G$2:G$401,"WEB") -> 216 | D39: =SUMIFS(DATA2026!E$2:E$401,DATA2026!A$2:A$401,"Q32026",DATA2026!G$2:G$401,"WEB") -> 672 | E39: =SUMIFS(DATA2026!E$2:E$401,DATA2026!A$2:A$401,"Q42026",DATA2026!G$2:G$401,"WEB") -> 0 | F39: =SUMIF(DATA2026!G$2:G$401,"WEB",DATA2026!E$2:E$401) -> 888
A40: Desktop | B40: =SUMIFS(DATA2026!E$2:E$401,DATA2026!A$2:A$401,"Q12026",DATA2026!G$2:G$401,"Desktop") -> 0 | C40: =SUMIFS(DATA2026!E$2:E$401,DATA2026!A$2:A$401,"Q22026",DATA2026!G$2:G$401,"Desktop") -> 444 | D40: =SUMIFS(DATA2026!E$2:E$401,DATA2026!A$2:A$401,"Q32026",DATA2026!G$2:G$401,"Desktop") -> 489 | E40: =SUMIFS(DATA2026!E$2:E$401,DATA2026!A$2:A$401,"Q42026",DATA2026!G$2:G$401,"Desktop") -> 0 | F40: =SUMIF(DATA2026!G$2:G$401,"Desktop",DATA2026!E$2:E$401) -> 933
A41: W->D | B41: =SUMIFS(DATA2026!E$2:E$401,DATA2026!A$2:A$401,"Q12026",DATA2026!G$2:G$401,"W->D") -> 0 | C41: =SUMIFS(DATA2026!E$2:E$401,DATA2026!A$2:A$401,"Q22026",DATA2026!G$2:G$401,"W->D") -> 0 | D41: =SUMIFS(DATA2026!E$2:E$401,DATA2026!A$2:A$401,"Q32026",DATA2026!G$2:G$401,"W->D") -> 78 | E41: =SUMIFS(DATA2026!E$2:E$401,DATA2026!A$2:A$401,"Q42026",DATA2026!G$2:G$401,"W->D") -> 0 | F41: =SUMIF(DATA2026!G$2:G$401,"W->D",DATA2026!E$2:E$401) -> 78
A42: D->W | B42: =SUMIFS(DATA2026!E$2:E$401,DATA2026!A$2:A$401,"Q12026",DATA2026!G$2:G$401,"D->W") -> 0 | C42: =SUMIFS(DATA2026!E$2:E$401,DATA2026!A$2:A$401,"Q22026",DATA2026!G$2:G$401,"D->W") -> 0 | D42: =SUMIFS(DATA2026!E$2:E$401,DATA2026!A$2:A$401,"Q32026",DATA2026!G$2:G$401,"D->W") -> 30 | E42: =SUMIFS(DATA2026!E$2:E$401,DATA2026!A$2:A$401,"Q42026",DATA2026!G$2:G$401,"D->W") -> 0 | F42: =SUMIF(DATA2026!G$2:G$401,"D->W",DATA2026!E$2:E$401) -> 30
A44: PO-BACKLOG — Einträge pro Quartal zugewiesen
B45: Q1 | C45: Q2 | D45: Q3 | E45: Q4 | F45: Gesamt
A46: Aus PO-Backlog | B46: =COUNTIFS(DATA2026!A$2:A$401,"Q12026",DATA2026!H$2:H$401,"PO-Backlog") -> 0 | C46: =COUNTIFS(DATA2026!A$2:A$401,"Q22026",DATA2026!H$2:H$401,"PO-Backlog") -> 0 | D46: =COUNTIFS(DATA2026!A$2:A$401,"Q32026",DATA2026!H$2:H$401,"PO-Backlog") -> 2 | E46: =COUNTIFS(DATA2026!A$2:A$401,"Q42026",DATA2026!H$2:H$401,"PO-Backlog") -> 2 | F46: =COUNTIF(DATA2026!H$2:H$401,"PO-Backlog") -> 4
A48: ℹ️ W->D und D->W werden je 50% auf Team Web und Team Desktop angerechnet | 🟡 Gelbe Einträge auf der Roadmap = aus PO-Backlog | Kapazitäten aus Roadmap-Blatt

Sheet Q12026
A1: Q12026
A2: # | B2: Projekttitel | C2: Größe | D2: Value-Bucket | E2: Quartal | F2: MoSCoW | G2: Team | H2: Std. | I2: Bemerkungen
A3: 1 | H3: =IF(C3="XXL (>160h)",168,IF(C3="XL (>40h)",48,IF(C3="L (20-40h)",30,IF(C3="M (10-20h)",15,IF(C3="S (<10h)",5,""))))) | J3: =IF($E3="Q12026",COUNTIF($E$3:$E3,"Q12026"),"") | K3: =IF($E3="Q22026",COUNTIF($E$3:$E3,"Q22026"),"") | L3: =IF($E3="Q32026",COUNTIF($E$3:$E3,"Q32026"),"") | M3: =IF($E3="Q42026",COUNTIF($E$3:$E3,"Q42026"),"") | N3: =IF($E3="Backlog",COUNTIF($E$3:$E3,"Backlog"),"")
A4: 2 | H4: =IF(C4="XXL (>160h)",168,IF(C4="XL (>40h)",48,IF(C4="L (20-40h)",30,IF(C4="M (10-20h)",15,IF(C4="S (<10h)",5,""))))) | J4: =IF($E4="Q12026",COUNTIF($E$3:$E4,"Q12026"),"") | K4: =IF($E4="Q22026",COUNTIF($E$3:$E4,"Q22026"),"") | L4: =IF($E4="Q32026",COUNTIF($E$3:$E4,"Q32026"),"") | M4: =IF($E4="Q42026",COUNTIF($E$3:$E4,"Q42026"),"") | N4: =IF($E4="Backlog",COUNTIF($E$3:$E4,"Backlog"),"")
A5: 3 | H5: =IF(C5="XXL (>160h)",168,IF(C5="XL (>40h)",48,IF(C5="L (20-40h)",30,IF(C5="M (10-20h)",15,IF(C5="S (<10h)",5,""))))) | J5: =IF($E5="Q12026",COUNTIF($E$3:$E5,"Q12026"),"") | K5: =IF($E5="Q22026",COUNTIF($E$3:$E5,"Q22026"),"") | L5: =IF($E5="Q32026",COUNTIF($E$3:$E5,"Q32026"),"") | M5: =IF($E5="Q42026",COUNTIF($E$3:$E5,"Q42026"),"") | N5: =IF($E5="Backlog",COUNTIF($E$3:$E5,"Backlog"),"")
A6: 4 | H6: =IF(C6="XXL (>160h)",168,IF(C6="XL (>40h)",48,IF(C6="L (20-40h)",30,IF(C6="M (10-20h)",15,IF(C6="S (<10h)",5,""))))) | J6: =IF($E6="Q12026",COUNTIF($E$3:$E6,"Q12026"),"") | K6: =IF($E6="Q22026",COUNTIF($E$3:$E6,"Q22026"),"") | L6: =IF($E6="Q32026",COUNTIF($E$3:$E6,"Q32026"),"") | M6: =IF($E6="Q42026",COUNTIF($E$3:$E6,"Q42026"),"") | N6: =IF($E6="Backlog",COUNTIF($E$3:$E6,"Backlog"),"")
A7: 5 | H7: =IF(C7="XXL (>160h)",168,IF(C7="XL (>40h)",48,IF(C7="L (20-40h)",30,IF(C7="M (10-20h)",15,IF(C7="S (<10h)",5,""))))) | J7: =IF($E7="Q12026",COUNTIF($E$3:$E7,"Q12026"),"") | K7: =IF($E7="Q22026",COUNTIF($E$3:$E7,"Q22026"),"") | L7: =IF($E7="Q32026",COUNTIF($E$3:$E7,"Q32026"),"") | M7: =IF($E7="Q42026",COUNTIF($E$3:$E7,"Q42026"),"") | N7: =IF($E7="Backlog",COUNTIF($E$3:$E7,"Backlog"),"")
A8: 6 | H8: =IF(C8="XXL (>160h)",168,IF(C8="XL (>40h)",48,IF(C8="L (20-40h)",30,IF(C8="M (10-20h)",15,IF(C8="S (<10h)",5,""))))) | J8: =IF($E8="Q12026",COUNTIF($E$3:$E8,"Q12026"),"") | K8: =IF($E8="Q22026",COUNTIF($E$3:$E8,"Q22026"),"") | L8: =IF($E8="Q32026",COUNTIF($E$3:$E8,"Q32026"),"") | M8: =IF($E8="Q42026",COUNTIF($E$3:$E8,"Q42026"),"") | N8: =IF($E8="Backlog",COUNTIF($E$3:$E8,"Backlog"),"")
A9: 7 | H9: =IF(C9="XXL (>160h)",168,IF(C9="XL (>40h)",48,IF(C9="L (20-40h)",30,IF(C9="M (10-20h)",15,IF(C9="S (<10h)",5,""))))) | J9: =IF($E9="Q12026",COUNTIF($E$3:$E9,"Q12026"),"") | K9: =IF($E9="Q22026",COUNTIF($E$3:$E9,"Q22026"),"") | L9: =IF($E9="Q32026",COUNTIF($E$3:$E9,"Q32026"),"") | M9: =IF($E9="Q42026",COUNTIF($E$3:$E9,"Q42026"),"") | N9: =IF($E9="Backlog",COUNTIF($E$3:$E9,"Backlog"),"")
A10: 8 | H10: =IF(C10="XXL (>160h)",168,IF(C10="XL (>40h)",48,IF(C10="L (20-40h)",30,IF(C10="M (10-20h)",15,IF(C10="S (<10h)",5,""))))) | J10: =IF($E10="Q12026",COUNTIF($E$3:$E10,"Q12026"),"") | K10: =IF($E10="Q22026",COUNTIF($E$3:$E10,"Q22026"),"") | L10: =IF($E10="Q32026",COUNTIF($E$3:$E10,"Q32026"),"") | M10: =IF($E10="Q42026",COUNTIF($E$3:$E10,"Q42026"),"") | N10: =IF($E10="Backlog",COUNTIF($E$3:$E10,"Backlog"),"")
A11: 9 | H11: =IF(C11="XXL (>160h)",168,IF(C11="XL (>40h)",48,IF(C11="L (20-40h)",30,IF(C11="M (10-20h)",15,IF(C11="S (<10h)",5,""))))) | J11: =IF($E11="Q12026",COUNTIF($E$3:$E11,"Q12026"),"") | K11: =IF($E11="Q22026",COUNTIF($E$3:$E11,"Q22026"),"") | L11: =IF($E11="Q32026",COUNTIF($E$3:$E11,"Q32026"),"") | M11: =IF($E11="Q42026",COUNTIF($E$3:$E11,"Q42026"),"") | N11: =IF($E11="Backlog",COUNTIF($E$3:$E11,"Backlog"),"")
